2025-09-28 09:38:41,818 uagents_core.utils.registration INFO Registering with Almanac API
2025-09-28 09:38:43,332 uagents_core.utils.registration INFO Registering with Almanac API
2025-09-28 09:38:44,800 uagents_core.utils.registration INFO Registering with Almanac API
2025-09-28 09:38:46,202 uagents_core.utils.registration INFO Registering with Almanac API
2025-09-28 09:38:47,833 uagents_core.utils.registration INFO Registering with Almanac API
2025-09-28 09:38:49,013 uagents_core.utils.registration ERROR Agent quota reached 5 / 4
Traceback (most recent call last):
  File "/Users/arslankamchybekov/Desktop/VSCode Projects/rockefeller/server/venv/lib/python3.13/site-packages/uagents_core/utils/registration.py", line 139, in _send_http_request_agentverse
    response.raise_for_status()
    ~~~~~~~~~~~~~~~~~~~~~~~~~^^
  File "/Users/arslankamchybekov/Desktop/VSCode Projects/rockefeller/server/venv/lib/python3.13/site-packages/requests/models.py", line 1026, in raise_for_status
    raise HTTPError(http_error_msg, response=self)
requests.exceptions.HTTPError: 406 Client Error: Not Acceptable for url: https://agentverse.ai/v1/agents
2025-09-28 09:38:49,018 uagents_core.utils.registration INFO Registering with Almanac API
2025-09-28 09:38:50,485 uagents_core.utils.registration ERROR Agent quota reached 5 / 4
Traceback (most recent call last):
  File "/Users/arslankamchybekov/Desktop/VSCode Projects/rockefeller/server/venv/lib/python3.13/site-packages/uagents_core/utils/registration.py", line 139, in _send_http_request_agentverse
    response.raise_for_status()
    ~~~~~~~~~~~~~~~~~~~~~~~~~^^
  File "/Users/arslankamchybekov/Desktop/VSCode Projects/rockefeller/server/venv/lib/python3.13/site-packages/requests/models.py", line 1026, in raise_for_status
    raise HTTPError(http_error_msg, response=self)
requests.exceptions.HTTPError: 406 Client Error: Not Acceptable for url: https://agentverse.ai/v1/agents
2025-09-28 09:38:50,489 uagents_core.utils.registration INFO Registering with Almanac API
2025-09-28 09:38:51,578 uagents_core.utils.registration ERROR Agent quota reached 5 / 4
Traceback (most recent call last):
  File "/Users/arslankamchybekov/Desktop/VSCode Projects/rockefeller/server/venv/lib/python3.13/site-packages/uagents_core/utils/registration.py", line 139, in _send_http_request_agentverse
    response.raise_for_status()
    ~~~~~~~~~~~~~~~~~~~~~~~~~^^
  File "/Users/arslankamchybekov/Desktop/VSCode Projects/rockefeller/server/venv/lib/python3.13/site-packages/requests/models.py", line 1026, in raise_for_status
    raise HTTPError(http_error_msg, response=self)
requests.exceptions.HTTPError: 406 Client Error: Not Acceptable for url: https://agentverse.ai/v1/agents
2025-09-28 09:38:51,581 uagents_core.utils.registration INFO Registering with Almanac API
2025-09-28 09:38:52,733 uagents_core.utils.registration ERROR Agent quota reached 5 / 4
Traceback (most recent call last):
  File "/Users/arslankamchybekov/Desktop/VSCode Projects/rockefeller/server/venv/lib/python3.13/site-packages/uagents_core/utils/registration.py", line 139, in _send_http_request_agentverse
    response.raise_for_status()
    ~~~~~~~~~~~~~~~~~~~~~~~~~^^
  File "/Users/arslankamchybekov/Desktop/VSCode Projects/rockefeller/server/venv/lib/python3.13/site-packages/requests/models.py", line 1026, in raise_for_status
    raise HTTPError(http_error_msg, response=self)
requests.exceptions.HTTPError: 406 Client Error: Not Acceptable for url: https://agentverse.ai/v1/agents
